Workbook
Name Slicer_Area: #N/A
Name Slicer_Criticality: #N/A
Name Slicer_Equipment_Type: #N/A
Name Slicer_Maintenance_Type: #N/A
Name Timeline_Month_Start: #N/A

Sheet Dashboard
B2: EQUIPMENT DOWNTIME & MAINTENANCE COST
B3: Fabrication Workshop · Feb 2025 – Jul 2026 · All figures INR
B4: Chart titles describe the full unfiltered dataset. Apply slicers to explore subsets.
B6: =Engine!A2 -> 29937396 | E6: =Engine!B2 -> 3845 | H6: =Engine!C2 -> 686 | K6: =Engine!D2 -> 5.6049563 | N6: =Engine!B7/Engine!B8 -> 0.98238277
B7: Total Downtime Cost | E7: Total Downtime Hours | H7: Total Events | K7: Avg Hours per Event | N7: Unplanned Share of Cost

Sheet Data
A1: Event_ID | B1: Event_Start | C1: Event_End | D1: Month_Start | E1: Maintenance_Type | F1: Equipment_ID | G1: Equipment_Name | H1: Equipment_Type | I1: Area | J1: Criticality | K1: Failure_Type | L1: Shift | M1: Crew | N1: Downtime_Hours | O1: Labour_Hours | P1: Parts_Cost_INR | Q1: Loss_Rate_Per_Hour | R1: Labour_Cost | S1: Production_Loss | T1: Total_Event_Cost | U1: Month_Label
A2: DT-2000 | B2: 45690.146 | C2: 45690.433 | D2: 45689 | E2: Unplanned | F2: SBM-01 | G2: Shot Blasting Machine | H2: Surface Treatment | I2: Blasting & Paint | J2: B | K2: Consumable / Wear | L2: Night | M2: Mech Crew B | N2: 6.9 | O2: 4.1 | P2: 2650 | Q2: 3300 | R2: 1968 | S2: 22770 | T2: 27388 | U2: 25-02 Feb
A3: DT-2003 | B3: 45692.344 | C3: 45692.59 | D3: 45689 | E3: Unplanned | F3: SBM-01 | G3: Shot Blasting Machine | H3: Surface Treatment | I3: Blasting & Paint | J3: B | K3: Consumable / Wear | L3: Day | M3: Mech Crew A | N3: 5.9 | O3: 4.2 | P3: 100 | Q3: 3300 | R3: 2016 | S3: 19470 | T3: 21586 | U3: 25-02 Feb
A4: DT-2002 | B4: 45692.104 | C4: 45692.429 | D4: 45689 | E4: Unplanned | F4: CMP-02 | G4: Screw Air Compressor #2 | H4: Air Compressor | I4: Utilities | J4: A | K4: Lubrication | L4: Night | M4: Contract - Vendor AMC | N4: 7.8 | O4: 5.7 | P4: 2900 | Q4: 9500 | R4: 2736 | S4: 74100 | T4: 79736 | U4: 25-02 Feb
A5: DT-2001 | B5: 45690.667 | C5: 45690.775 | D5: 45689 | E5: Unplanned | F5: WLD-SA1 | G5: SAW Welding Station 1 | H5: Welding Equipment | I5: Fabrication Bay 1 | J5: B | K5: Mechanical | L5: General | M5: Elect Crew A | N5: 2.6 | O5: 2.7 | P5: 13650 | Q5: 2800 | R5: 1296 | S5: 7280 | T5: 22226 | U5: 25-02 Feb
A6: DT-2004 | B6: 45692.906 | C6: 45693.102 | D6: 45689 | E6: Unplanned | F6: WLD-SA2 | G6: SAW Welding Station 2 | H6: Welding Equipment | I6: Fabrication Bay 2 | J6: B | K6: Control / Software | L6: Night | M6: Elect Crew B | N6: 4.7 | O6: 4.5 | P6: 12500 | Q6: 2800 | R6: 2160 | S6: 13160 | T6: 27820 | U6: 25-02 Feb
A7: DT-2005 | B7: 45692.927 | C7: 45693.14 | D7: 45689 | E7: Unplanned | F7: CRN-02 | G7: EOT Crane 10T Bay-2 | H7: Overhead Crane | I7: Fabrication Bay 2 | J7: B | K7: Mechanical | L7: Night | M7: Elect Crew A | N7: 5.1 | O7: 3.5 | P7: 9250 | Q7: 7200 | R7: 1680 | S7: 36720 | T7: 47650 | U7: 25-02 Feb
A8: DT-2006 | B8: 45693.333 | C8: 45693.483 | D8: 45689 | E8: Planned | F8: PLC-02 | G8: Profile Gas Cutting Machine | H8: Cutting Machine | I8: Cutting Shop | J8: B | K8: Preventive Maintenance | L8: Day | M8: Elect Crew B | N8: 3.6 | O8: 7.2 | P8: 4650 | Q8: 5400 | R8: 3456 | S8: 0 | T8: 8106 | U8: 25-02 Feb
A9: DT-2007 | B9: 45693.333 | C9: 45693.554 | D9: 45689 | E9: Planned | F9: ROL-01 | G9: Plate Rolling Machine | H9: Forming Machine | I9: Fabrication Bay 2 | J9: B | K9: Preventive Maintenance | L9: Day | M9: Mech Crew A | N9: 5.3 | O9: 10.6 | P9: 4550 | Q9: 6100 | R9: 5088 | S9: 0 | T9: 9638 | U9: 25-02 Feb
A10: DT-2008 | B10: 45693.333 | C10: 45693.546 | D10: 45689 | E10: Planned | F10: CMP-01 | G10: Screw Air Compressor #1 | H10: Air Compressor | I10: Utilities | J10: A | K10: Preventive Maintenance | L10: Day | M10: Mech Crew B | N10: 5.1 | O10: 10.2 | P10: 2250 | Q10: 9500 | R10: 4896 | S10: 0 | T10: 7146 | U10: 25-02 Feb
A11: DT-2009 | B11: 45693.552 | C11: 45693.802 | D11: 45689 | E11: Unplanned | F11: CMP-02 | G11: Screw Air Compressor #2 | H11: Air Compressor | I11: Utilities | J11: A | K11: Mechanical | L11: Day | M11: Mech Crew A | N11: 6 | O11: 4.4 | P11: 15200 | Q11: 9500 | R11: 2112 | S11: 57000 | T11: 74312 | U11: 25-02 Feb
A12: DT-2010 | B12: 45697.083 | C12: 45697.363 | D12: 45689 | E12: Unplanned | F12: PLC-01 | G12: CNC Plasma Cutting Machine | H12: Cutting Machine | I12: Cutting Shop | J12: A | K12: Consumable / Wear | L12: Night | M12: Elect Crew A | N12: 6.7 | O12: 2.5 | P12: 5950 | Q12: 5400 | R12: 1200 | S12: 36180 | T12: 43330 | U12: 25-02 Feb
A13: DT-2011 | B13: 45700.333 | C13: 45700.425 | D13: 45689 | E13: Planned | F13: WLD-SA2 | G13: SAW Welding Station 2 | H13: Welding Equipment | I13: Fabrication Bay 2 | J13: B | K13: Preventive Maintenance | L13: Day | M13: Mech Crew B | N13: 2.2 | O13: 4.4 | P13: 4250 | Q13: 2800 | R13: 2112 | S13: 0 | T13: 6362 | U13: 25-02 Feb
... A687: DT-2685 | B687: 46233.323 | C687: 46233.444 | D687: 46204 | E687: Unplanned | F687: CMP-02 | G687: Screw Air Compressor #2 | H687: Air Compressor | I687: Utilities | J687: A | K687: Operator Error | L687: Day | M687: Contract - Vendor AMC | N687: 2.9 | O687: 2.8 | P687: 1500 | Q687: 9500 | R687: 1344 | S687: 27550 | T687: 30394 | U687: 26-07 Jul

Sheet Analysis
A1: ANALYSIS — Equipment Downtime & Maintenance Cost, Feb 2025 – Jul 2026
B4: Row Labels | C4: Events | D4: Downtime Hrs | E4: Parts | F4: Labour | G4: Prod. Loss | H4: Total Cost | I4: % of Cost | J4: Avg Hrs/Event | N4: Over 18 months the plant recorded 686 maintenance events costing ₹2.99 crore. Only 58 were planned; 628 were breakdowns, accounting for 98.2% of the cost. Of the total, ₹2.36 crore (79%) is lost production rather than maintenance spend — a figure that depends entirely on the client's stated loss rates and needs validating against actual output data before it drives any investment decision.
B5: Planned | C5: 58 | D5: 265.8 | E5: 242150 | F5: 285264 | G5: 0 | H5: 527414 | I5: 0.01761723 | J5: 4.5827586
B6: Unplanned | C6: 628 | D6: 3579.2 | E6: 4094350 | F6: 1704432 | G6: 23611200 | H6: 29409982 | I6: 0.98238277 | J6: 5.6993631
B7: Grand Total | C7: 686 | D7: 3845 | E7: 4336500 | F7: 1989696 | G7: 23611200 | H7: 29937396 | I7: 1 | J7: 5.6049563
B13: Equipment_ID | C13: Equipment_Name | D13: Criticality | E13: Area | F13: Count of Event_ID | G13: Sum of Downtime_Hours | H13: Sum of Total_Event_Cost | I13: Sum of Total_Event_Cost2 | K13: Cumulative % | N13: Cost concentrates sharply: CMP-02 (₹78.3 lakh) and CRN-01 (₹68.3 lakh) together account for 49% of the plant's total downtime cost, and six of twelve assets reach 78%. Both leaders are A-criticality assets that also lead on event count — 104 and 93 events — so this is a recurrence problem, not a few expensive one-off failures.
B14: CMP-02 | C14: Screw Air Compressor #2 | D14: A | E14: Utilities | F14: 104 | G14: 732.7 | H14: 7827328 | I14: 0.26145654 | K14: =SUM($I$14:I14) -> 0.26145654
B15: CRN-01 | C15: EOT Crane 20T Bay-1 | D15: A | E15: Fabrication Bay 1 | F15: 93 | G15: 800.6 | H15: 6825376 | I15: 0.2279883 | K15: =SUM($I$14:I15) -> 0.48944484
B16: PRS-01 | C16: Hydraulic Press 300T | D16: A | E16: Fabrication Bay 1 | F16: 51 | G16: 395.9 | H16: 2809452 | I16: 0.093844234 | K16: =SUM($I$14:I16) -> 0.58328907
B17: CMP-01 | C17: Screw Air Compressor #1 | D17: A | E17: Utilities | F17: 52 | G17: 204.6 | H17: 2100592 | I17: 0.070166156 | K17: =SUM($I$14:I17) -> 0.65345523
B18: CRN-02 | C18: EOT Crane 10T Bay-2 | D18: B | E18: Fabrication Bay 2 | F18: 46 | G18: 250.7 | H18: 2082562 | I18: 0.069563899 | K18: =SUM($I$14:I18) -> 0.72301913
B19: PLC-01 | C19: CNC Plasma Cutting Machine | D19: A | E19: Cutting Shop | F19: 51 | G19: 278 | H19: 1789602 | I19: 0.059778145 | K19: =SUM($I$14:I19) -> 0.78279727
B20: ROL-01 | C20: Plate Rolling Machine | D20: B | E20: Fabrication Bay 2 | F20: 38 | G20: 220.3 | H20: 1619266 | I20: 0.054088405 | K20: =SUM($I$14:I20) -> 0.83688568
B21: SBM-01 | C21: Shot Blasting Machine | D21: B | E21: Blasting & Paint | F21: 59 | G21: 299.6 | H21: 1367606 | I21: 0.045682196 | K21: =SUM($I$14:I21) -> 0.88256788
B22: PLC-02 | C22: Profile Gas Cutting Machine | D22: B | E22: Cutting Shop | F22: 43 | G22: 180.8 | H22: 1221572 | I22: 0.040804217 | K22: =SUM($I$14:I22) -> 0.92337209
B23: WLD-SA1 | C23: SAW Welding Station 1 | D23: B | E23: Fabrication Bay 1 | F23: 61 | G23: 186.7 | H23: 897328 | I23: 0.029973482 | K23: =SUM($I$14:I23) -> 0.95334557
B24: WLD-SA2 | C24: SAW Welding Station 2 | D24: B | E24: Fabrication Bay 2 | F24: 54 | G24: 173.1 | H24: 802634 | I24: 0.026810415 | K24: =SUM($I$14:I24) -> 0.98015599
B25: PNT-01 | C25: Airless Paint Spray Unit | D25: C | E25: Blasting & Paint | F25: 34 | G25: 122 | H25: 594078 | I25: 0.01984401 | K25: =SUM($I$14:I25) -> 1
B26: Grand Total | F26: 686 | G26: 3845 | H26: 29937396 | I26: 1
B31: Maintenance_Type | C31: All
B33: Row Labels | C33: Count of Event_ID | D33: Sum of Downtime_Hours | E33: Avg Hrs/Event | F33: Sum of Total_Event_Cost | G33: Avg Cost/Event | N33: Mechanical (172 events) and electrical (153) failures are 52% of all breakdowns and ₹1.69 crore of cost. But frequency and severity point different ways: lubrication failures occur only 32 times yet cost ₹68,504 per event, the highest of any category, against ₹20,841 for consumable wear. Frequent-and-cheap and rare-and-expensive are two separate problems needing two separate responses.
B34: Mechanical | C34: 172 | D34: 1104.8 | E34: 6.4232558 | F34: 9726490 | G34: 56549.36
B35: Electrical | C35: 153 | D35: 897.6 | E35: 5.8666667 | F35: 7186236 | G35: 46968.863
B36: Consumable / Wear | C36: 71 | D36: 285.3 | E36: 4.0183099 | F36: 1479706 | G36: 20840.93
B37: Preventive Maintenance | C37: 58 | D37: 265.8 | E37: 4.5827586 | F37: 527414 | G37: 9093.3448
B38: Pneumatic | C38: 54 | D38: 294.5 | E38: 5.4537037 | F38: 2816154 | G38: 52151
B39: Operator Error | C39: 40 | D39: 223.2 | E39: 5.58 | F39: 1630704 | G39: 40767.6
B40: Hydraulic | C40: 39 | D40: 254.5 | E40: 6.525641 | F40: 2202350 | G40: 56470.513
B41: Control / Software | C41: 33 | D41: 133.9 | E41: 4.0575758 | F41: 969698 | G41: 29384.788
B42: Lubrication | C42: 32 | D42: 241.7 | E42: 7.553125 | F42: 2192122 | G42: 68503.812
B43: No Fault Found | C43: 23 | D43: 69.3 | E43: 3.0130435 | F43: 470038 | G43: 20436.435
B44: Structural | C44: 11 | D44: 74.4 | E44: 6.7636364 | F44: 736484 | G44: 66953.091
B45: Grand Total | C45: 686 | D45: 3845 | E45: 5.6049563 | F45: 29937396 | G45: 43640.519
C51: Column Labels
C52: Planned | E52: Unplanned | G52: Total Count of Event_ID | H52: Total Sum of Total_Event_Cost
B53: Row Labels | C53: Count of Event_ID | D53: Sum of Total_Event_Cost | E53: Count of Event_ID | F53: Sum of Total_Event_Cost | I53: Breakdowns per PM | N53: Nine of twelve assets sit between 5.8 and 11.2 breakdowns per preventive job. CMP-02 records 33.7 and CRN-01 45.5 — and the difference is the denominator, not the numerator: those two received 3 and 2 PMs in 18 months against 5–6 for every other asset. The clearest evidence is the compressor pair: CMP-01 and CMP-02 are identical machines in the same area, but CMP-01 had 6 PMs, 46 breakdowns and ₹21 lakh of cost, while CMP-02 had 3 PMs, 101 breakdowns and ₹78 lakh. Direction of causation cannot be established from this data — skipped PM may cause breakdowns, or constant breakdowns may crowd out the PM window — and duty-cycle parity between the two compressors needs confirming before the comparison can be relied on.
B54: CMP-01 | C54: 6 | D54: 47464 | E54: 46 | F54: 2053128 | G54: 52 | H54: 2100592 | I54: =IFERROR(E54/C54, "NO PM") -> 7.6666667
B55: CMP-02 | C55: 3 | D55: 30672 | E55: 101 | F55: 7796656 | G55: 104 | H55: 7827328 | I55: =IFERROR(E55/C55, "NO PM") -> 33.666667
B56: CRN-01 | C56: 2 | D56: 18124 | E56: 91 | F56: 6807252 | G56: 93 | H56: 6825376 | I56: =IFERROR(E56/C56, "NO PM") -> 45.5
B57: CRN-02 | C57: 5 | D57: 48450 | E57: 41 | F57: 2034112 | G57: 46 | H57: 2082562 | I57: =IFERROR(E57/C57, "NO PM") -> 8.2
...

Sheet Forecast
A1: Source: Engine monthly pivot, Unplanned only. Static copy — update manually if data changes.
A3: Month | B3: Actual_Cost | C3: t | D3: 3M_MA | F3: Linear Trend | U3: Month | V3: Actual | W3: 3M Moving Average | X3: Trend Forecast | Y3: High (+25%) | Z3: Low (−25%) | AA3: Divider
A4: 25-02 Feb | B4: 1385074 | C4: 1 | U4: 25-02 Feb | V4: {=B4} -> 1385074
A5: 25-03 Mar | B5: 1139860 | C5: 2 | E5: Slope | F5: =SLOPE($B$4:$B$21,$C$4:$C$21) -> 55565.253 | H5: =SLOPE(B4:B18,C4:C18) -> 25786.379 | U5: 25-03 Mar | V5: {=B5} -> 1139860
A6: 25-04 Apr | B6: 1657484 | C6: 3 | D6: =AVERAGE(B4:B6) -> 1394139.3 | E6: Intercept | F6: =INTERCEPT($B$4:$B$21,$C$4:$C$21) -> 1106018 | H6: =INTERCEPT(B4:B18,C4:C18) -> 1289634.3 | U6: 25-04 Apr | V6: {=B6} -> 1657484 | W6: =D6 -> 1394139.3
A7: 25-05 May | B7: 1600230 | C7: 4 | D7: =AVERAGE(B5:B7) -> 1465858 | U7: 25-05 May | V7: {=B7} -> 1600230 | W7: =D7 -> 1465858
A8: 25-06 Jun | B8: 1345210 | C8: 5 | D8: =AVERAGE(B6:B8) -> 1534308 | U8: 25-06 Jun | V8: {=B8} -> 1345210 | W8: =D8 -> 1534308
A9: 25-07 Jul | B9: 1543666 | C9: 6 | D9: =AVERAGE(B7:B9) -> 1496368.7 | U9: 25-07 Jul | V9: {=B9} -> 1543666 | W9: =D9 -> 1496368.7
A10: 25-08 Aug | B10: 1005472 | C10: 7 | D10: =AVERAGE(B8:B10) -> 1298116 | U10: 25-08 Aug | V10: {=B10} -> 1005472 | W10: =D10 -> 1298116
A11: 25-09 Sep | B11: 1492534 | C11: 8 | D11: =AVERAGE(B9:B11) -> 1347224 | U11: 25-09 Sep | V11: {=B11} -> 1492534 | W11: =D11 -> 1347224
A12: 25-10 Oct | B12: 1689528 | C12: 9 | D12: =AVERAGE(B10:B12) -> 1395844.7 | U12: 25-10 Oct | V12: {=B12} -> 1689528 | W12: =D12 -> 1395844.7
A13: 25-11 Nov | B13: 1442172 | C13: 10 | D13: =AVERAGE(B11:B13) -> 1541411.3 | U13: 25-11 Nov | V13: {=B13} -> 1442172 | W13: =D13 -> 1541411.3
A14: 25-12 Dec | B14: 1376572 | C14: 11 | D14: =AVERAGE(B12:B14) -> 1502757.3 | U14: 25-12 Dec | V14: {=B14} -> 1376572 | W14: =D14 -> 1502757.3
A15: 26-01 Jan | B15: 1844782 | C15: 12 | D15: =AVERAGE(B13:B15) -> 1554508.7 | U15: 26-01 Jan | V15: {=B15} -> 1844782 | W15: =D15 -> 1554508.7
A16: 26-02 Feb | B16: 1270398 | C16: 13 | D16: =AVERAGE(B14:B16) -> 1497250.7 | U16: 26-02 Feb | V16: {=B16} -> 1270398 | W16: =D16 -> 1497250.7
A17: 26-03 Mar | B17: 1384354 | C17: 14 | D17: =AVERAGE(B15:B17) -> 1499844.7 | U17: 26-03 Mar | V17: {=B17} -> 1384354 | W17: =D17 -> 1499844.7
A18: 26-04 Apr | B18: 2261544 | C18: 15 | D18: =AVERAGE(B16:B18) -> 1638765.3 | U18: 26-04 Apr | V18: {=B18} -> 2261544 | W18: =D18 -> 1638765.3
A19: 26-05 May | B19: 1970056 | C19: 16 | D19: =AVERAGE(B17:B19) -> 1871984.7 | I19: =$H$5*C19+$H$6 -> 1702216.4 | J19: =ABS(I19-B19)/B19 -> 0.13595534 | U19: 26-05 May | V19: {=B19} -> 1970056 | W19: =D19 -> 1871984.7
A20: 26-06 Jun | B20: 1954756 | C20: 17 | D20: =AVERAGE(B18:B20) -> 2062118.7 | I20: =$H$5*C20+$H$6 -> 1728002.7 | J20: =ABS(I20-B20)/B20 -> 0.1160008 | U20: 26-06 Jun | V20: {=B20} -> 1954756 | W20: =D20 -> 2062118.7
A21: 26-07 Jul | B21: 3046290 | C21: 18 | D21: =AVERAGE(B19:B21) -> 2323700.7 | I21: =$H$5*C21+$H$6 -> 1753789.1 | J21: =ABS(I21-B21)/B21 -> 0.42428688 | U21: 26-07 Jul | V21: {=B21} -> 3046290 | W21: =D21 -> 2323700.7 | X21: =V21 -> 3046290 | Y21: =V21 -> 3046290 | Z21: =V21 -> 3046290 | AA21: =3500000 -> 3500000
I22: MAPE | J22: =AVERAGE(J19:J21) -> 0.22541434 | K22: *** | L22: Backtested on a 15-month fit, this model was 22.5% off over three held-out months and under-predicted the worst month by 42%. Treat the projection as an order-of-magnitude planning figure, not a budget line." | U22: 26-08 Aug | X22: =$F$5*C24+$F$6 -> 2161757.8 | Y22: =X22*1.25 -> 2702197.2 | Z22: =X22*0.75 -> 1621318.3
E23: Low (−25%) | F23: High (+25%) | U23: 26-09 Sep | X23: =$F$5*C25+$F$6 -> 2217323 | Y23: =X23*1.25 -> 2771653.8 | Z23: =X23*0.75 -> 1662992.3
A24: 46235 | C24: 19 | D24: =$F$5*C24+$F$6 -> 2161757.8 | E24: =D24*0.75 -> 1621318.3 | F24: =D24*1.25 -> 2702197.2 | U24: 26-10 Oct | X24: =$F$5*C26+$F$6 -> 2272888.3 | Y24: =X24*1.25 -> 2841110.4 | Z24: =X24*0.75 -> 1704666.2
A25: 46266 | C25: 20 | D25: =$F$5*C25+$F$6 -> 2217323 | E25: =D25*0.75 -> 1662992.3 | F25: =D25*1.25 -> 2771653.8 | U25: 26-11 Nov | X25: =$F$5*C27+$F$6 -> 2328453.5 | Y25: =X25*1.25 -> 2910566.9 | Z25: =X25*0.75 -> 1746340.2
A26: 46296 | C26: 21 | D26: =$F$5*C26+$F$6 -> 2272888.3 | E26: =D26*0.75 -> 1704666.2 | F26: =D26*1.25 -> 2841110.4 | U26: 26-12 Dec | X26: =$F$5*C28+$F$6 -> 2384018.8 | Y26: =X26*1.25 -> 2980023.5 | Z26: =X26*0.75 -> 1788014.1
A27: 46327 | C27: 22 | D27: =$F$5*C27+$F$6 -> 2328453.5 | E27: =D27*0.75 -> 1746340.2 | F27: =D27*1.25 -> 2910566.9 | U27: 27-01 Jan | X27: =$F$5*C29+$F$6 -> 2439584.1 | Y27: =X27*1.25 -> 3049480.1 | Z27: =X27*0.75 -> 1829688
A28: 46357 | C28: 23 | D28: =$F$5*C28+$F$6 -> 2384018.8 | E28: =D28*0.75 -> 1788014.1 | F28: =D28*1.25 -> 2980023.5
A29: 46388 | C29: 24 | D29: =$F$5*C29+$F$6 -> 2439584.1 | E29: =D29*0.75 -> 1829688 | F29: =D29*1.25 -> 3049480.1
A34: Equpment ID | B34: CMP-01 | C34: CMP-02 | D34: Difference
A35: PMs | B35: 6 | C35: 3
A36: Total Event Cost | B36: 2100592 | C36: 7827328 | D36: =C36-B36 -> 5726736

Sheet Read Me
A1: EQUIPMENT DOWNTIME & MAINTENANCE COST ANALYSIS
A3: 1. Replace the source file in 01_Source_Data with the new export (same column layout)
A4: 2. Data → Refresh All
A5: 3. Every figure, chart and KPI updates automatically
A6: 4. To change cost rates, edit the Rates sheet in the source file and refresh
A8: Cost model. The formula block from your scope note, exactly as written, plus the exclusions.
A10: Assumptions and limitations
A11: Production loss applies to unplanned events only, per client's stated basis
A12: Loss rates are client-supplied; the 79% loss share is highly sensitive to them
A13: Shifts compared on mean hours per event, not counts — exposure hours are not recorded
A14: Causation between skipped PM and breakdown frequency cannot be established from this data
A15: Duty-cycle parity between CMP-01 and CMP-02 is assumed and unconfirmed
A16: Forecast is a linear trend on 18 months; backtest MAPE 22.5%
A18: Version and date. | C18: v05 · September 2026 · Sudhansu Kumar Biswal

Sheet Engine
A1: Sum of Total_Event_Cost | B1: Sum of Downtime_Hours | C1: Count of Event_ID | D1: Average of Downtime_Hours2
A2: 29937396 | B2: 3845 | C2: 686 | D2: 5.6049563
A5: Row Labels | B5: Sum of Total_Event_Cost | C5: Count of Event_ID
A6: Planned | B6: 527414 | C6: 58
A7: Unplanned | B7: 29409982 | C7: 628
A8: Grand Total | B8: 29937396 | C8: 686
A12: Row Labels | B12: Sum of Total_Event_Cost
A13: CMP-02 | B13: 7827328
A14: CRN-01 | B14: 6825376
A15: PRS-01 | B15: 2809452
A16: CMP-01 | B16: 2100592
A17: CRN-02 | B17: 2082562
A18: PLC-01 | B18: 1789602
A19: ROL-01 | B19: 1619266
A20: SBM-01 | B20: 1367606
A21: PLC-02 | B21: 1221572
A22: WLD-SA1 | B22: 897328
A23: WLD-SA2 | B23: 802634
A24: PNT-01 | B24: 594078
A25: Grand Total | B25: 29937396
A28: Maintenance_Type | B28: All
A30: Row Labels | B30: Sum of Total_Event_Cost | C30: Average of Downtime_Hours
A31: 25-02 Feb | B31: 1486712 | C31: 5.2119048
A32: 25-03 Mar | B32: 1139860 | C32: 5.4074074
A33: 25-04 Apr | B33: 1657484 | C33: 5.205
A34: 25-05 May | B34: 1629928 | C34: 5.8081081
A35: 25-06 Jun | B35: 1412666 | C35: 5.5685714
A36: 25-07 Jul | B36: 1543666 | C36: 5.58
A37: 25-08 Aug | B37: 1050050 | C37: 4.4575758
A38: 25-09 Sep | B38: 1492534 | C38: 6.0193548
A39: 25-10 Oct | B39: 1745844 | C39: 5.0170213
A40: 25-11 Nov | B40: 1482014 | C40: 5.1102564
A41: 25-12 Dec | B41: 1376572 | C41: 6.1185185
A42: 26-01 Jan | B42: 1844782 | C42: 6.1078947
... A49: Grand Total | B49: 29937396 | C49: 5.6049563
A53: Maintenance_Type | B53: Unplanned
A55: Row Labels | B55: Count of Event_ID | C55: Average of Total_Event_Cost
A56: Mechanical | B56: 172 | C56: 56549.36
A57: Electrical | B57: 153 | C57: 46968.863
A58: Consumable / Wear | B58: 71 | C58: 20840.93
...
